Exception in Tkinter callback
Traceback (most recent call last):
  File "/home/dews/anaconda3/lib/python3.6/tkinter/__init__.py", line 1705, in __call__
    return self.func(*args)
  File "/home/dews/Scrivania/CC4CS/src/__init__.py", line 150, in callback
    inptGen = InputsGenerator(absFunctionFile, functionName)
  File "/home/dews/Scrivania/CC4CS/src/InputsGenerator.py", line 11, in __init__
    self.paramsList = self.discoverParameters()
  File "/home/dews/Scrivania/CC4CS/src/InputsGenerator.py", line 25, in discoverParameters
    raise ValueError("Function not found")
ValueError: Function not found

